Workbook
Name DET_JUL: #REF!
Name FEBRERO: [1]FEB!$A$6:$H$71
Name DET_JUN: #REF!
Name PEDERNALES: #REF!
Name ANEXO7: #REF!
Name TextRefCopy9: #REF!
Name TextRefCopy6: [2]no!$G$63
Name TextRefCopy45: '[9]Ajuste Anual'!#REF!
Name TextRefCopy26: #REF!
Name BALANZA_JULIO: '[6]07'!$A$1:$IV$65536
Name REL: #REF!
Name BALANZA_FEBRERO: '[6]02'!$A$1:$IV$65536
Name SJJ: #REF!
Name SMGZ: [16]VARIABLES!$B$8
Name TextRefCopy35: #REF!
Name PARCIAL5: #REF!
Name TextRefCopy8: #REF!
Name CEDULA_2.2: #REF!
Name TextRefCopy32: #REF!
Name TextRefCopy36: [19]Resultados!$B$7
Name F_YOLIQ: #REF!
Name ANEXO1: #REF!
Name TextRefCopy38: [19]Resultados!$B$18
Name Ref_1: [13]inventarios!#REF!
Name TextRefCopy47: '[9]Ajuste Anual'!#REF!
Name PROMEDIO: #REF!
Name ALIMENTOS_1: #REF!
Name TextRefCopy34: [19]Conciliacion!$D$9
Name CUENTAS: #REF!
Name K_RESUM1: #REF!
Name TextRefCopy21: #REF!
Name AMBIT09: #REF!
Name M_CONC: #REF!
Name NIDIA: '[9]Ajuste Anual'!#REF!
Name DET_AGO: #REF!
Name AGOSTO: [1]AGO!$A$6:$H$84
Name Rango1: #REF!
Name NADA2: [11]Inventarios!#REF!
Name CIASA: #REF!
Name TABLA1: [6]TABLA1!$A$6:$M$71
Name N_RESUM3: #REF!
Name TABLON: '[17]INPC (2)'!$A$5:$M$68
Name TextRefCopy37: [19]Resultados!$B$10
Name CAPITAL: #REF!
Name TextRefCopy54: #REF!
Name TextRefCopy30: #REF!
Name SAGABRIEL: #REF!
Name BALANZA_MAYO: '[6]05'!$A$1:$IV$65536
Name CAT: #REF!
Name RESUMEN: [14]Procesos!$A$4:$B$29
Name TABLA2: [6]TABLA1!$A$5:$M$72
Name TextRefCopy49: #REF!
Name INTRODUCCION: #REF!
Name TextRefCopy46: '[9]Ajuste Anual'!#REF!
Name Y: [20]Conciliacion!$D$9
Name TextRefCopy29: #REF!
Name H_QUESO: #REF!
Name POLIZA: #REF!
Name A_impresión_IM: #REF!
Name PARCIAL1: #REF!

Sheet CUCA
B2: ==+CCF!A2
B3: CUENTA DE CAPITAL DE APORTACIÓN (CUCA)
B8: TIPO DE MOVIMIENTO | C8: FEHA | D8: MONTO | E8: CAPITAL SOCIAL (HISTORICO) | F8: INPC FECHA DEL MOVIMIENTO | H8: INPC DE ACTUALIZACIÓN | J8: FACTOR DE ACTUALIZACIÓN | K8: CAP. SOCIAL ACT. MAS/MENOS AUMENTO O DISMINUCIÓN DE CAPITAL | L8: CAPITAL SOCIAL ACTUALIZADO
B13: APORTACIÓN INICIAL | C13: 39853 | D13: 0 | E13: ==+D13 | F13: ==+C13 | G13: 69.609494 | H13: 40148 | I13: 71.771855 | J13: ==TRUNC(+I13/G13,4) | L13: ==+E13*J13
B14: ACTUALIZACION A 2010 | E14: ==+E13 | F14: 40148 | G14: 71.771855 | H14: 40513 | I14: 74.930954 | J14: ==TRUNC(+I14/G14,4) | K14: ==+L13 | L14: ==J14*K14
B15: ACTUALIZACION A 2011 | E15: ==+E14 | F15: 40513 | G15: 74.930954 | H15: 40878 | I15: 77.792385 | J15: ==TRUNC(+I15/G15,4) | K15: ==+L14 | L15: ==J15*K15
B16: ACTUALIZACION A 2012 | E16: ==+E15 | F16: 40878 | G16: 77.792385 | H16: 41244 | I16: 80.568243 | J16: ==TRUNC(+I16/G16,4) | K16: ==+L15 | L16: ==J16*K16
B17: ACTUALIZACION A 2013 | E17: ==+E16 | F17: 41244 | G17: 80.568243 | H17: 41609 | I17: 83.770058 | J17: ==TRUNC(+I17/G17,4) | K17: ==+L16 | L17: ==J17*K17
B18: ACTUALIZACION A 2014 | E18: ==+E17 | F18: 41609 | G18: 83.770058 | H18: 41974 | I18: 87.188984 | J18: ==TRUNC(+I18/G18,4) | K18: ==+L17 | L18: ==J18*K18
B19: ACTUALIZACION A 2015 | E19: ==+E18 | F19: 41974 | G19: 87.188984 | H19: 42339 | I19: 89.046818 | J19: ==TRUNC(+I19/G19,4) | K19: ==+L18 | L19: ==J19*K19
B20: ACTUALIZACION A 2016 | D20: 0 | E20: ==+E19 | F20: 42339 | G20: ==+I19 | H20: 42705 | I20: 92.039035 | J20: ==TRUNC(+I20/G20,4) | K20: ==+L19 | L20: ==J20*K20
B21: APORTACIÓN INICIAL | C21: 42933 | D21: 200000 | E21: ==E20+D21 | F21: 42917 | G21: 95.322736 | H21: 43070 | I21: 98.272883 | J21: ==TRUNC(+I21/G21,4) | K21: ==+L20 | L21: ==+E21*J21
B22: ACTUALIZACION A 2018 | D22: 0 | E22: ==E21+D22 | F22: ==+H21 | G22: ==I21 | H22: 43435 | I22: 103.02 | J22: ==TRUNC(+I22/G22,4) | K22: ==+L21 | L22: ==J22*K22
B23: ACTUALIZACION A 2019 | D23: 0 | E23: ==E22+D23 | F23: ==+H22 | G23: ==I22 | H23: 43800 | I23: 105.934 | J23: ==TRUNC(+I23/G23,4) | K23: ==+L22 | L23: ==J23*K23
B24: ACTUALIZACION A 2020 | D24: 0 | E24: ==E23+D24 | F24: ==+H23 | G24: ==I23 | H24: 44166 | I24: 109.271 | J24: ==TRUNC(+I24/G24,4) | K24: ==+L23 | L24: ==J24*K24
B25: ACTUALIZACION A 2021 | E25: ==E24+D25 | F25: 44166 | G25: 109.271 | H25: 44531 | I25: 117.308 | J25: ==TRUNC(+I25/G25,4) | K25: ==+L24 | L25: ==J25*K25
B26: ACTUALIZACION A 2022 | E26: ==E25+D26 | F26: 44531 | G26: ==+I25 | H26: 44896 | I26: 126.478 | J26: ==TRUNC(+I26/G26,4) | K26: ==+L25 | L26: ==J26*K26
B27: ACTUALIZACION A 2023 | E27: ==E26+D27 | F27: ==+H26 | G27: ==+I26 | H27: 45261 | I27: 132.373 | J27: ==TRUNC(+I27/G27,4) | K27: ==+L26 | L27: ==J27*K27
B28: ACTUALIZACION A 2024 | E28: ==E27+D28 | F28: ==+H27 | G28: ==+I27 | H28: 45627 | I28: 137.949 | J28: ==TRUNC(+I28/G28,4) | K28: ==+L27 | L28: ==J28*K28
J31: ==TRUNC(+I26/G21,4) | L31: ==+D21*J31
L32: ==+L31-L26

Sheet CUFIN
A2: ==+CCF!A2
A3: DETERMINACION DE SALDO DE CUFIN 2014 EN ADELANT
B6: 2014 | C6: 2015 | D6: 2016 | E6: 2017 | F6: 2018 | G6: 2019 | H6: 2020 | I6: 2021 | J6: 2022 | K6: 2023 | L6: 2024
A8: RESULTADO FISCAL | B8: 0 | C8: 0 | D8: 0 | E8: 65148 | F8: 47265 | G8: 63635 | H8: 0 | I8: 119623.18 | J8: 0 | K8: 0 | L8: ==+CCF!D84
A10: ISR PAGADO ANUAL | B10: ==+B8*0.3 | C10: ==+C8*0.3 | D10: ==+D8*0.3 | E10: ==+E8*0.3 | F10: ==+F8*0.3 | G10: ==+G8*0.3 | H10: ==+H8*0.3 | I10: ==+I8*0.3 | J10: ==+J8*0.3 | K10: 0 | L10: ==+L8*0.3
A12: NO DEDUCIBLES | B12: 0 | C12: 0 | D12: 0 | E12: 0 | F12: 34061 | G12: 97565 | H12: 2515 | I12: 269252.4 | J12: 147060 | K12: 133883.31 | L12: ==+CCF!B55
A14: DECRETO DE DIVIDENDOS | B14: 0 | C14: 0 | D14: 0 | E14: 0 | F14: 0 | G14: 0 | H14: 0 | I14: 0 | J14: 0 | K14: 0 | L14: 0
A16: PTU pagada Art10 f-1
A19: CUFIN | B19: ==+B8-B10-B12-B14-B16 | C19: ==+C8-C10-C12-C14-C16 | D19: ==+D8-D10-D12-D14-D16 | E19: ==+E8-E10-E12-E14-E16 | F19: ==+F8-F10-F12-F14-F16 | G19: ==+G8-G10-G12-G14-G16 | H19: ==+H8-H10-H12-H14-H16 | I19: ==+I8-I10-I12-I14-I16 | ... L19: ==+L8-L10-L12-L14-L16
B22: DIC.2013 | C22: ==+B25 | D22: ==+C25 | E22: ==+D25 | F22: ==+E25 | G22: ==+F25 | H22: ==+G25 | I22: ==+H25 | J22: DIC.2021 | K22: DIC.2022 | L22: ==+K25
B23: 83.77 | C23: ==+B26 | D23: ==+C26 | E23: ==+D26 | F23: ==+E26 | G23: ==+F26 | H23: ==+G26 | I23: ==+H26 | J23: 117.308 | K23: 126.478 | L23: ==+K26
B25: DIC.2014 | C25: DIC.2015 | D25: DIC.2016 | E25: DIC.2017 | F25: DIC.2018 | G25: DIC.2019 | H25: DIC.2020 | I25: DIC.2021 | J25: DIC.2022 | K25: DIC.2023 | L25: DIC.2024
B26: 87.189 | C26: 89.047 | D26: 92.039 | E26: 98.273 | F26: 103.02 | G26: 105.934 | H26: 109.271 | I26: 117.308 | J26: 126.478 | K26: 132.373 | L26: 137.949
A28: FACTOR ACTUALIZACION | B28: ==TRUNC(B26/B23,4) | C28: ==TRUNC(C26/C23,4) | D28: ==TRUNC(D26/D23,4) | E28: ==TRUNC(E26/E23,4) | F28: ==TRUNC(F26/F23,4) | G28: ==TRUNC(G26/G23,4) | H28: ==TRUNC(H26/H23,4) | I28: ==TRUNC(I26/I23,4) | ... L28: ==TRUNC(L26/L23,4)
A36: Cufin Actualizada al cierre del año ANTERIOR | B36: 0 | C36: ==+B39 | D36: ==+C39 | E36: ==+D39 | F36: ==+E39 | G36: ==+F39 | H36: ==+G39 | I36: ==+H39 | J36: ==+I39 | ... L36: ==+K39
A38: Cufin actual. del año anterior | B38: ==+B36*B28 | C38: ==+C36*C28 | D38: ==+D36*D28 | E38: ==+E36*E28 | F38: ==+F36*F28 | G38: ==+G36*G28 | H38: ==+H36*H28 | I38: ==+I36*I28 | ... L38: ==+L36*L28
A39: Cufin acumulada | B39: ==+B38+B19 | C39: ==+C38+C19 | D39: ==+D38+D19 | E39: ==+E38+E19 | F39: ==+F38+F19 | G39: ==+G38+G19 | H39: ==+H38+H19 | I39: ==+I38+I19 | ... L39: ==+L38+L19

Sheet CCF
A2: ==+ER!B9 | D2: Resultado
D3: del Ejercicio
A4: DETERMINACION DE DECLARACION ANUAL 2024 ISR | D4: ==+ER!H70 | E4: ==+C17-C48-D4
A6: " Ingresos según Estado de Resultados "
A8: INGRESOS | B8: ==+ER!H18
A9: ING X RETRABAJOS | B9: 0
A10: INGRESOS POR ACTUALIZACION | B10: 0
A11: DEV SOBRE VENTA | B11: 0
A12: PRODUCTOS FINANCIEROS | B12: ==+ER!H61
A13: REND BANCARIOS | B13: 0
A14: OTROS PROD | B14: ==+ER!H56
A15: OTROS ING NO ACUMULABLES | B15: 0
A17: Total ingresos según Estado de Resultados | C17: ==SUM(B7:B16) | G17: 8777497 | H17: ==+C17-G17
A19: INGRESOS CONTABLES NO FISCALES:
A21: ACTUALIZACION DEV DE IMPUESTOS | B21: ==+BAL!#REF!
A22: VENTA DE ACTIVOS | B22: 0
A23: Anticipos de clientes ( Ejercicio año anterior ) | B23: ==272809*0
A24: Otros Ingresos NO Acumulables
C25: ==SUM(B20:B24) | G25: ==+B14-C25
A26: INGRESOS FISCALES NO CONTABLES:
A28: INVENTARIO ACUMULABLE | B28: 0
A29: AJUSTE ANUAL X INF ACUMULABLE | B29: 172725
A30: ANTICIPO DE CLIENTES 2022 ( Ejercicio actual ) | B30: ==+BAL!G79 | G30: ==+D36-B29
A31: UTILIDAD EN VENTA DE ACTIVO FIJO | B31: ==+B22 | G31: 8777496.7
A32: Disponible | B32: 0
A33: Disponible | B33: 0 | G33: ==+G31-G30
C34: ==SUM(B28:B34)
G35: 10963446
A36: Total Ingresos Acumulables | D36: ==C17-C25+C34 | G36: ==+D36-C34 | I36: 11150829 | J36: ==+D36-I36
G37: ==+G35-G36
A38: " Deducciones según Estado de Resultados "
A40: COSTO DE VENTAS | B40: ==+ER!H23 | G40: 11916261
A41: GASTOS GENERALES | B41: ==+ER!H51 | G41: ==+G36-G40
A42: GASTOS FINANCIEROS | B42: ==-ER!H62
A43: DEV SOBRE VENTA | B43: 0
A44: OTROS GASTOS | B44: 0
A45: OTROS GASTOS (ISR+PTU) | B45: 0
A46: Disponible | B46: 0
A48: Total de gastos según estado de resultados: | C48: ==SUM(B40:B47) | E48: ==+C17-C48-D4
A50: Deducciones Contables NO Fiscales :
...

Sheet BG
B7: AL SERVICIOS MULTIPLES EMPRESARIALES SA DE CV
B8: Balance General
B9: Al 31 de Julio de 2026
B10: (Importes expresados en pesos)
C13: A C T I V O | I13: P A S I V O
C14: C I R C U L A N T E | I14: C I R C U L A N T E
B16: Caja Chica | E16: ==+BAL!G7 | H16: Proveedores | K16: ==+BAL!G61
B17: Bancos | E17: ==+BAL!G9 | H17: Acreedores Diversos | K17: ==+(BAL!G62/4)
B18: Inversiones y Valores | E18: ==+BAL!G17 | H18: Anticipos de Clientes | K18: ==+BAL!G79
B19: Cuentas por Cobrar | E19: ==+BAL!G23 | H19: Impuestos por Pagar | K19: ==+BAL!G81
B20: Contribuciones | E20: ==+BAL!G38+BAL!G35+BAL!G32+BAL!G31 | H20: Otros Pasivos PTU | K20: ==+BAL!G90
B21: Inventarios | E21: ==+BAL!G33 | K21: ==SUM(K16:K20)
B22: Deudores Diversos | E22: ==+BAL!G28
B23: Anticipo a Proveedores | E23: ==+BAL!G45 | I23: PASIVO A LARGO PLAZO
B24: Pagos anticipados | E24: ==+BAL!G43 | H24: Acreedores Diversos | K24: ==+K17*4-K17-0.03
B26: TOTAL CIRCULANTE | F26: ==SUM(E16:E24) | H26: TOTAL PASIVO | L26: ==SUM(K15:K20)+K24
C28: NO CIRCULANTE
B29: Herramientas | E29: 0 | I29: C A P I T A L
B30: Mobiliario y Equipo | E30: ==+BAL!G48 | I30: C O N T A B L E
B31: Equipo de Cómputo | E31: ==+BAL!G51 | H31: Capital Social | K31: ==+BAL!G91
B32: Equipo de transporte | E32: ==+BAL!G54 | H32: Aportaciones para aumentos de Capital | K32: ==+BAL!G94
B33: Maquinaria y Equipo | E33: ==+BAL!G58 | H33: Resultados de Ejercicios Ant. | K33: ==+BAL!G95
B34: Depreciacion acumulada de activos | E34: ==-BAL!G50-BAL!G53-BAL!G57-BAL!G60 | H34: Resultado del Ejercicio | K34: ==+ER!H70
B36: TOTAL NO CIRCULANTE | F36: ==SUM(E29:E34) | H36: TOTAL CAPITAL CONTABLE | L36: ==SUM(K31:K34)
C38: OTROS ACTIVOS
B39: Depósitos en Garantía | E39: 0
B40: Pagos Anticipados | E40: 0
B42: TOTAL OTROS ACTIVOS | F42: ==SUM(E39:E40)
B45: TOTAL DEL ACTIVO | F45: ==F26+F36+F42 | H45: TOTAL PASIVO+CAPITAL CONTABLE | L45: ==L26+L36-0
L47: ==+F45-L45
F48: ==+F45-L45
B58: C. P. SERGIO ALEJANDRO CHAVARRÍA SOLÍS | J58: LIC. GABRIELA TORRES RAMIREZ
B59: CEDULA PROFESIONAL 7997330 | J59: REPRESENTANTE LEGAL
B60: CONTADOR EXTERNO | C60: CONTADOR EXTERNO

Sheet ER
B9: AL SERVICIOS MULTIPLES EMPRESARIALES SA DE CV
B10: Estado de Resultados
B11: Del 1ro de Enero al 31 de Julio 2026
B12: (Importes expresados en pesos)
D15: Del Período | F15: % | H15: Acumulado | J15: %
B17: I N G R E S O S
B18: Ingresos por servicios | D18: #REF! | F18: 1.0001 | H18: ==+BAL!G105-H56 | J18: 1.0001
B19: Descuentos o bonificaciones | H19: 0 | J19: 0
B20: INGRESOS NETOS | H20: ==SUM(H18:H19) | J20: ==IF($H$18=0,0,H20/$H$18)
B22: C O S T O S
B23: Costo de Ventas | D23: 0 | F23: #REF! | H23: ==+BAL!G110+BAL!G119 | J23: ==IF($H$18=0,0,H23/$H$18)
B25: UTILIDAD BRUTA | D25: #REF! | F25: #REF! | H25: ==+H20-H23 | J25: ==IF($H$18=0,0,H25/$H$18)
B27: Gastos de Operación
B28: Sueldos y Salarios | D28: #REF! | F28: #REF! | H28: ==+BAL!G120 | J28: ==IF($H$18=0,0,H28/$H$18)
B29: Impuestos y Derechos | H29: ==+BAL!G135 | J29: ==IF($H$18=0,0,H29/$H$18)
B30: Honorarios | D30: #REF! | F30: #REF! | H30: ==+BAL!G141 | J30: ==IF($H$18=0,0,H30/$H$18)
B31: Arrendamiento | D31: #REF! | F31: #REF! | H31: ==+BAL!G144 | J31: ==IF($H$18=0,0,H31/$H$18)
B32: Seguros y Fianzas | D32: #REF! | F32: #REF! | H32: ==+BAL!G147 | J32: ==IF($H$18=0,0,H32/$H$18)
B33: Servicios | D33: #REF! | F33: #REF! | H33: ==+BAL!G148 | J33: ==IF($H$18=0,0,H33/$H$18)
B34: Capacitación al Personal | D34: #REF! | F34: #REF! | H34: ==+BAL!G152 | J34: ==IF($H$18=0,0,H34/$H$18)
B35: Fletes y/o Mensajería | D35: #REF! | F35: #REF! | H35: ==+BAL!G153+BAL!G154 | J35: ==IF($H$18=0,0,H35/$H$18)
B36: Seguridad e higiene | H36: ==+BAL!G155 | J36: ==IF($H$18=0,0,H36/$H$18)
B37: Mantenimiento | D37: #REF! | F37: #REF! | H37: ==+BAL!G157 | J37: ==IF($H$18=0,0,H37/$H$18)
B38: Combustibles | D38: #REF! | F38: #REF! | H38: ==+BAL!G161 | J38: ==IF($H$18=0,0,H38/$H$18)
B39: Propaganda y Publicidad | D39: #REF! | F39: #REF! | H39: ==+BAL!G160 | J39: ==IF($H$18=0,0,H39/$H$18)
B40: Cuotas y Suscripciones | D40: #REF! | F40: #REF! | H40: ==+BAL!G163 | J40: ==IF($H$18=0,0,H40/$H$18)
B41: Gastos de Viaje | D41: #REF! | F41: #REF! | H41: ==+BAL!G164 | J41: ==IF($H$18=0,0,H41/$H$18)
B42: Herrajes y Herramientas | H42: ==+BAL!G166 | J42: ==IF($H$18=0,0,H42/$H$18)
B43: Papelería y Art. de Oficina | D43: #REF! | F43: #REF! | H43: ==+BAL!G162 | J43: ==IF($H$18=0,0,H43/$H$18)
B44: Depreciaciones | D44: #REF! | F44: #REF! | H44: ==+BAL!G167 | J44: ==IF($H$18=0,0,H44/$H$18)
B45: Recargos | D45: #REF! | F45: #REF! | H45: ==+BAL!G168 | J45: ==IF($H$18=0,0,H45/$H$18)
B46: Varios | D46: #REF! | F46: #REF! | H46: ==+BAL!G169+BAL!G156+BAL!G165 | J46: ==IF($H$18=0,0,H46/$H$18)
B47: Uniformes | D47: #REF! | F47: #REF! | H47: ==+BAL!G170 | J47: ==IF($H$18=0,0,H47/$H$18)
D48: #REF! | F48: #REF! | J48: ==IF($H$18=0,0,H48/$H$18)
D49: #REF! | F49: #REF! | J49: ==IF($H$18=0,0,H49/$H$18)
B50: No deducibles | D50: #REF! | F50: #REF! | H50: ==+BAL!G171 | J50: ==IF($H$18=0,0,H50/$H$18)
B51: GASTOS DE OPERACIÓN | D51: #REF! | F51: #REF! | H51: ==SUM(H28:H50) | J51: ==IF($H$18=0,0,H51/$H$18)
B53: UTILIDAD O (PÉRDIDA) DE OPERACIÓN | D53: #REF! | F53: #REF! | H53: ==+H25-H51 | J53: ==IF($H$18=0,0,H53/$H$18)
B55: OTROS INGRESOS Y GASTOS
B56: Otros Productos | D56: #REF! | F56: #REF! | H56: ==+BAL!G109 | J56: ==IF($H$18=0,0,H56/$H$18)
...

Sheet BAL
C1: AL SERVICIOS MULTIPLES EMPRESARIALES SA DE CV
C2: Balanza de Comprobación
C3: JULIO.2026
C4: RFC: SME170717GA0 | M4: ==+L5-K5
K5: ==SUBTOTAL(9,K7:K215) | L5: ==SUBTOTAL(9,L7:L247)
C6: CUENTA | D6: SALDO INICIAL | E6: DEBE | F6: HABER | G6: SALDO FINAL
A7: * | B7: 1 | C7: 1110 CAJA Y EFECTIVO | D7: 1324.44 | E7: 0 | F7: 0 | G7: 1324.44 | H7: ==IF(I7=C7,"ok","REVISAR") | I7: 1110 CAJA Y EFECTIVO | J7: 1324.44 | K7: 0 | L7: 0 | M7: 1324.44
B8: 2 | C8: 1110-0001 CAJA Y EFECTIVO | D8: 1324.44 | G8: 1324.44 | H8: ==IF(I8=C8,"ok","REVISAR") | I8: 1110-0001 CAJA Y EFECTIVO | J8: 1324.44 | M8: 1324.44
A9: * | B9: 1 | C9: 1120 BANCOS | D9: -1008205.8 | E9: 0 | F9: 584.64 | G9: -1008790.5 | H9: ==IF(I9=C9,"ok","REVISAR") | I9: 1120 BANCOS | J9: -1008205.8 | K9: 0 | L9: 584.64 | M9: -1008790.5
B10: 2 | C10: 1120-0001 BBVA BANCOMER | D10: -1331003.1 | F10: 584.64 | G10: -1331587.7 | H10: ==IF(I10=C10,"ok","REVISAR") | I10: 1120-0001 BBVA BANCOMER | J10: -1331003.1 | L10: 584.64 | M10: -1331587.7
B11: 1 | C11: 1120-0002 SANTANDER | D11: 301648.18 | G11: 301648.18 | H11: ==IF(I11=C11,"ok","REVISAR") | I11: 1120-0002 SANTANDER | J11: 301648.18 | M11: 301648.18
B12: 2 | C12: 1120-0003 BBVA BANCOMER DOLARES | D12: 244.4019 | E12: 0 | F12: 0 | G12: 244.4019 | H12: ==IF(I12=C12,"ok","REVISAR") | I12: 1120-0003 BBVA BANCOMER DOLARES | J12: 244.4019 | K12: 0 | L12: 0 | M12: 244.4019
B13: 1 | C13: 1120-0003-0001 BBVA DOLARES | D13: 14.11 | G13: 14.11 | H13: ==IF(I13=C13,"ok","REVISAR") | I13: 1120-0003-0001 BBVA DOLARES | J13: 14.11 | M13: 14.11
B14: 2 | C14: 1120-0003-0002 BBVA COMPLEMENTARIA | D14: 230.2919 | G14: 230.2919 | H14: ==IF(I14=C14,"ok","REVISAR") | I14: 1120-0003-0002 BBVA COMPLEMENTARIA | J14: 230.2919 | M14: 230.2919
B15: 1 | C15: 1120-0006 ACTINVER CONTRATO 174493893 | D15: 0.010000002 | G15: 0.01 | H15: ==IF(I15=C15,"ok","REVISAR") | I15: 1120-0006 ACTINVER CONTRATO 174493893 | J15: 0.010000002 | M15: 0.01
B16: 2 | C16: 1120-0009 BANORTE | D16: 20904.7 | G16: 20904.7 | H16: ==IF(I16=C16,"ok","REVISAR") | I16: 1120-0009 BANORTE | J16: 20904.7 | M16: 20904.7
A17: * | B17: 1 | C17: 1125 INVERSIONES Y VALORES | D17: 479239.98 | E17: 0 | F17: 0 | G17: 479239.98 | H17: ==IF(I17=C17,"ok","REVISAR") | I17: 1125 INVERSIONES Y VALORES | J17: 479239.98 | K17: 0 | L17: 0 | M17: 479239.98
C18: 1125-0002 ACTINVER BOLSA CONTRATO 7129911 | D18: 479230.97 | G18: 479230.97 | H18: ==IF(I18=C18,"ok","REVISAR") | I18: 1125-0002 ACTINVER BOLSA CONTRATO 7129911 | J18: 479230.97 | M18: 479230.97
B19: 2 | C19: 1125-0003 ACTINVER BOLSA CONTRATO 7129911 DLLS | D19: 9.01 | E19: 0 | F19: 0 | G19: 9.01 | H19: ==IF(I19=C19,"ok","REVISAR") | I19: 1125-0003 ACTINVER BOLSA CONTRATO 7129911 DLLS | J19: 9.01 | K19: 0 | L19: 0 | M19: 9.01
B20: 1 | C20: 1125-0003-0001 DOLARES | D20: 0.52 | G20: 0.52 | H20: ==IF(I20=C20,"ok","REVISAR") | I20: 1125-0003-0001 DOLARES | J20: 0.52 | M20: 0.52
B21: 2 | C21: 1125-0003-0002 COMPLEMENTARIA | D21: 8.5 | G21: 8.5 | H21: ==IF(I21=C21,"ok","REVISAR") | I21: 1125-0003-0002 COMPLEMENTARIA | J21: 8.5 | M21: 8.5
B22: 1 | C22: 1125-0003-0003 VALUACION | D22: -0.01 | G22: -0.01 | H22: ==IF(I22=C22,"ok","REVISAR") | I22: 1125-0003-0003 VALUACION | J22: -0.01 | M22: -0.01
A23: * | B23: 2 | C23: 1130 CLIENTES | H23: ==IF(I23=C23,"ok","REVISAR") | I23: 1130 CLIENTES
B24: 1 | C24: 1130-0001 CLIENTES NACIONALES | H24: ==IF(I24=C24,"ok","REVISAR") | I24: 1130-0001 CLIENTES NACIONALES
B25: 2 | C25: 1130-TSPS TS PRODUCTS AND SERVICES CO | H25: ==IF(I25=C25,"ok","REVISAR") | I25: 1130-TSPS TS PRODUCTS AND SERVICES CO
B26: 1 | C26: 1130-TSPS-COM TSPS COMPLEMENTARIA | H26: ==IF(I26=C26,"ok","REVISAR") | I26: 1130-TSPS-COM TSPS COMPLEMENTARIA
B27: 2 | C27: 1130-TSPS-DLLS TSPS DOLARES | H27: ==IF(I27=C27,"ok","REVISAR") | I27: 1130-TSPS-DLLS TSPS DOLARES
A28: * | B28: 1 | C28: 1150 FUNCIONARIOS Y EMPLEADOS | D28: 22890 | E28: 0 | F28: 0 | G28: 22890 | H28: ==IF(I28=C28,"ok","REVISAR") | I28: 1150 FUNCIONARIOS Y EMPLEADOS | J28: 22890 | K28: 0 | L28: 0 | M28: 22890
B29: 2 | C29: 1150-0001 DEUDORES DIVERSOS | D29: -2110 | G29: -2110 | H29: ==IF(I29=C29,"ok","REVISAR") | I29: 1150-0001 DEUDORES DIVERSOS | J29: -2110 | M29: -2110
B30: 1 | C30: 1150-VERA ADRIANA VELARDE | D30: 25000 | G30: 25000 | H30: ==IF(I30=C30,"ok","REVISAR") | I30: 1150-VERA ADRIANA VELARDE | J30: 25000 | M30: 25000
A31: * | B31: 2 | C31: 1160 IVA ACREDITABLE | D31: 24042.216 | E31: 80.64 | G31: 24122.856 | H31: ==IF(I31=C31,"ok","REVISAR") | I31: 1160 IVA ACREDITABLE | J31: 24042.216 | K31: 80.64 | M31: 24122.856
A32: * | B32: 1 | C32: 1167 IVA ACREDITABLE NO PAGADO | D32: 110107.78 | G32: 110107.78 | H32: ==IF(I32=C32,"ok","REVISAR") | I32: 1167 IVA ACREDITABLE NO PAGADO | J32: 110107.78 | M32: 110107.78
A33: * | B33: 2 | C33: 1170 INVENTARIO | H33: ==IF(I33=C33,"ok","REVISAR") | I33: 1170 INVENTARIO
B34: 1 | C34: 1170-0001 INVENTARIO | H34: ==IF(I34=C34,"ok","REVISAR") | I34: 1170-0001 INVENTARIO
A35: * | B35: 2 | C35: 1190 IMPUESTOS | D35: 89386.94 | E35: 0 | F35: 0 | G35: 89386.94 | H35: ==IF(I35=C35,"ok","REVISAR") | I35: 1190 IMPUESTOS | J35: 89386.94 | K35: 0 | L35: 0 | M35: 89386.94
B36: 1 | C36: 1190-0001 ISR PAGOS PROVISIONALES | D36: 88966 | G36: 88966 | H36: ==IF(I36=C36,"ok","REVISAR") | I36: 1190-0001 ISR PAGOS PROVISIONALES | J36: 88966 | M36: 88966
B37: 2 | C37: 1190-0002 ISR RET BANCO | D37: 420.94 | G37: 420.94 | H37: ==IF(I37=C37,"ok","REVISAR") | I37: 1190-0002 ISR RET BANCO | J37: 420.94 | M37: 420.94
A38: * | B38: 1 | C38: 1195 CONTRIBUCIONES A FAVOR | D38: 2701821.4 | E38: 0 | F38: 0 | G38: 2701821.4 | H38: ==IF(I38=C38,"ok","REVISAR") | I38: 1195 CONTRIBUCIONES A FAVOR | J38: 2701821.4 | K38: 0 | L38: 0 | M38: 2701821.4
B39: 2 | C39: 1195-0001 IVA A FAVOR | D39: 2693178.3 | G39: 2693178.3 | H39: ==IF(I39=C39,"ok","REVISAR") | I39: 1195-0001 IVA A FAVOR | J39: 2693178.3 | M39: 2693178.3
B40: 1 | C40: 1195-0002 ISR A FAVOR | D40: 4653 | G40: 4653 | H40: ==IF(I40=C40,"ok","REVISAR") | I40: 1195-0002 ISR A FAVOR | J40: 4653 | M40: 4653
...

Sheet Res
B2: DECLARACION DEL EJERCICIO
B3: PERSONAS MORALES DEL REGIMEN GENERAL F18
B6: DATOS DE IDENTIFICACION
C8: RFC | G8: SME170717GA0
C10: DENOMINACION O RAZON SOCIAL | G10: ==+CCF!A2
B12: DATOS GENERALES
C14: TIPO DE DECLARACIÓN | G14: Normal | L14: TIPO DE COMPLEMENTARIA
C16: PERIODO | G16: Del Ejercicio | L16: EJERCICIO: | O16: 2024
C18: INDIQUE SI OPTA POR DICTAMINAR SUS ESTADOS FINANCIEROS | K18: NO
B20: DATOS DEL DOMICILIO FISCAL ( VIGENTE )
C22: DOMICILIO | N22: NUM EXTERIOR
C24: NUMERO INTERIOR | H24: COLONIA
C26: CODIGO POSTAL | H26: ESTADO | I26: Chihuahua | N26: CIUDAD | O26: Chihuahua
C28: CIEC | H28: FIEL
B30: Nota: Verificar que el domicilio fiscal y la FIEL esten vigentes
B32: RESUMEN INFORMATIVO
C34: Ventas Ejercicio Anterior | G34: 0 | K34: Deducciones autorizadas Ejerc Anterior | O34: 0
C36: Ventas Ejercicio Actual | G36: ==+[21]CCF!B8 | K36: Deducciones autorizadas Ejerc Actual | O36: ==+[21]CCF!D78
C38: Variacion de Ingresos | G38: ==+G36-G34 | J38: ==+G38/G34*100% | K38: Variacion de Deducciones autorizadas | O38: ==+O36-O34 | P38: ==+O38/O34*100%
C41: Variacion neta acumulada | G41: ==+G38-O38 | K41: Impacto en ISR del Ejercicio | O41: ==+G41*0.3
C43: ISR del Ejercicio anterior | G43: 0 | K43: Probable impto a determinar Ejec Actual | O43: ==+G43+O41
C45: Impacto Real en ISR del Ejercicio | G45: ==+O49-G43
C49: Ingresos acumulables año anterior | G49: 11850829 | K49: ISR del Ejercicio | O49: ==+CCF!D87*1
C51: Ingresos acumulables año actual | G51: ==+CCF!D36 | K51: ISR a Pagar Neto del año | O51: ==+CCF!D91*0 | R51: ==+G51-G49
C53: Resultado del ejercicio : | K53: % de ISR respecto a Ingresos Acum | O53: ==O49/G60
E54: Utilidad Fiscal: | G54: ==+CCF!D80*1
E56: Perdida Contable: | G56: ==+CCF!D4 | K56: % de ISR respecto a Utilidad Fiscal | O56: ==IFERROR(O49/G54,0)
E58: Perdida Fiscal: | G58: ==+CCF!D84*1 | K58: % de ISR respecto a Utilidad Contable | O58: ==IFERROR(O49/G56,0)
C60: Ingresos Acumulables del año | G60: ==+G51 | K60: ISR a Favor del año | O60: ==-CCF!D91*1
C62: Factor de utilidad utilizado en 2024 | H62: 0.0304 | I62: ==+H62 | K62: PTU a Pagar en Mayo del 2025 | O62: 2275
C63: Factor para el año 2025 | H63: ==IF((CCF!E84<0),H62,CCF!E84) | I63: ==+H63
C64: Diferencia en factor | H64: ==+H63-H62 | I64: ==+I63-I62 | K64: Perdida por amortizar para 2025 | O64: 1200449
C68: Fecha | E68: Realizó | I68: Revisó | N68: Autorizó
C70: FECHA y HORA DE PRESENTACIÓN | J70: NUMERO DE OPERACIÓN
G73: Sueldos | J73: Impuesto
C74: Informacion Timbrada Plataforma | G74: ==+ER!M28 | J74: 75993
C76: Informacion Nomina Contabilidad | G76: ==+ER!H28 | J76: 75993
C78: Diferencia | G78: ==+G74-G76 | J78: ==+J74-J76

Sheet Ret ISR Hon
C4: Impto Pagado | D4: Gasto
B5: Ene
B6: Feb
B7: Mar
B8: Abr
B9: May
B10: Jun
B11: Jul
B12: Ago
B13: Sep
B14: Oct
B15: Nov
B16: Dic
C17: ==SUM(C5:C16) | D17: ==SUM(D5:D16)
B19: Abonos Cuenta Contab
C20: ==+C17-C19 | D20: ==+D17-D19
